Workbook

Sheet Раздел 14
A2: Социально-экономические показатели по субъектам Российской Федерации
A3: 14. СТРОИТЕЛЬСТВО
B4: СТРОИТЕЛЬНАЯ ДЕЯТЕЛЬНОСТЬ
A5: 14.1. | B5: Объем работ, выполненных по виду экономической деятельности «Строительство»
A6: 14.2. | B6: Ввод в действие зданий жилого и нежилого назначения
A7: 14.2.1. | B7: Число зданий
A8: 14.2.2. | B8: Общая площадь зданий
B9: ЖИЛИЩНОЕ И СОЦИАЛЬНО-КУЛЬТУРНОЕ СТРОИТЕЛЬСТВО
A10: 14.3. | B10: Ввод в действие жилых домов
A11: 14.3.1. | B11: Всего
A12: 14.3.2. | B12: На 1000 человек населения
A13: 14.4. | B13: Ввод в действие квартир
A14: 14.4.1. | B14: Всего
A15: 14.4.2. | B15: На 1000 человек населения
A16: 14.5. | B16: Ввод в действие жилых домов, построенных жилищно-строительными кооперативами
A17: 14.6. | B17: Ввод в действие жилых домов, построенных населением за счет собственных и привлеченных средств
A18: 14.7. | B18: Число зданий и сооружений, находящихся в незавершенном строительстве
A19: 14.8. | B19: Жилые дома, находящиеся в незавершенном строительстве
A20: 14.9. | B20: Удельный вес жилых домов, построенных населением за счет собственных и привлеченных средств, в общем вводе жилья
A21: 14.10. | B21: Ввод в действие мощностей общеобразовательных организаций
... A29: 14.12.2. | B29: На 100000 человек населения

Sheet 14.1.
A2: Социально-экономические показатели по субъектам Российской Федерации
A3: 14. СТРОИТЕЛЬСТВО
A4: СТРОИТЕЛЬНАЯ ДЕЯТЕЛЬНОСТЬ
A5: 14.1. ОБЪЕМ РАБОТ, ВЫПОЛНЕННЫХ ПО ВИДУ ЭКОНОМИЧЕСКОЙ ДЕЯТЕЛЬНОСТИ «СТРОИТЕЛЬСТВО»1)
A6: (в фактически действовавших ценах; миллионов рублей)
B7: 2000 | C7: 2001 | D7: 2002 | E7: 2003 | F7: 2004 | G7: 2005 | H7: 2006 | I7: 2007 | J7: 2008 | K7: 2009 | L7: 2010 | M7: 2011 | N7: 2012 | O7: 2013 | P7: 2014 | Q7: 2015 | R7: 2016 | S7: 2017 | T7: 2018 | U7: 2019 | V7: 2020 | W7: 2021 | X7: 2022 | Y7: 2023 | Z7: 2024
A8: Российская Федерация | B8: 503836.8 | C8: 703831.3 | D8: 830995.5 | E8: 1042720.8 | F8: 1313550.5 | G8: 1754406.2 | H8: 2350840.4 | I8: 3293323.4 | J8: 4528144.7 | K8: 3998342 | L8: 4454156.1 | M8: 5140309.9 | N8: 5714109.3 | O8: 6019464.7 | P8: 6125191.2 | Q8: 7010355.7 | R8: 7213464.2 | S8: 7579837.9 | T8: 8470580.5 | U8: 9132153.1 | V8: 9686256.6 | W8: 11047948 | X8: 13149370 | Y8: 15244343 | Z8: 16780080
A9: Центральный федеральный округ | B9: =SUM(B10:B27) -> 144969.2 | C9: =SUM(C10:C27) -> 191698 | D9: =SUM(D10:D27) -> 224018.2 | E9: =SUM(E10:E27) -> 299631.4 | F9: =SUM(F10:F27) -> 391465.4 | G9: 517238.7 | H9: 706807.5 | I9: 942811.1 | J9: 1214848.3 | K9: 1068106.7 | L9: 1159676.1 | M9: 1270451.8 | N9: 1417953.4 | O9: 1492522.7 | P9: 1593876.3 | Q9: 1780675.5 | R9: 1842119 | S9: 1984091.3 | T9: 2157211.6 | U9: 2356914.4 | V9: 2626914.8 | W9: 2914419.4 | X9: 3545934.1 | Y9: 4054701.7 | Z9: 4256126.7
A10: Белгородская область | B10: 4572.6 | C10: 4581.7 | D10: 5356 | E10: 7383.4 | F10: 11636.6 | G10: 14760.7 | H10: 18543.5 | I10: 32723.9 | J10: 43588.6 | K10: 29832.4 | L10: 41302.7 | M10: 70808 | N10: 80017.7 | O10: 71282.4 | P10: 63342.7 | Q10: 76726.1 | R10: 70984.848 | S10: 88591.816 | T10: 92638.306 | U10: 118522.04 | V10: 127125 | W10: 123674.3 | X10: 146082.5 | Y10: 174327.4 | Z10: 200579.2
A11: Брянская область | B11: 2191.1 | C11: 2263.4 | D11: 2496.5 | E11: 2707.4 | F11: 3778.8 | G11: 4122.9 | H11: 4963.5 | I11: 8145.5 | J11: 11862 | K11: 11499 | L11: 13900.9 | M11: 16941.9 | N11: 18018.5 | O11: 22496.7 | P11: 23973.6 | Q11: 24983.8 | R11: 27764.391 | S11: 28564.571 | T11: 25316.516 | U11: 30334.971 | V11: 40518.5 | W11: 46429.6 | X11: 46223.4 | Y11: 47647.6 | Z11: 43405.2
A12: Владимирская область | B12: 2736.4 | C12: 3141.4 | D12: 3317.3 | E12: 3226.8 | F12: 4373.7 | G12: 6446.5 | H12: 8876.5 | I12: 16250.7 | J12: 20594.4 | K12: 20069 | L12: 21308.9 | M12: 23311.6 | N12: 27075.8 | O12: 30211.5 | P12: 32305.5 | Q12: 30576.2 | R12: 34277.68 | S12: 37927.043 | T12: 40515.002 | U12: 42923.933 | V12: 43864.7 | W12: 64536 | X12: 96585.7 | Y12: 110230.6 | Z12: 90497.7
A13: Воронежская область | B13: 3627.7 | C13: 4893.8 | D13: 6552.8 | E13: 8210.5 | F13: 9494.5 | G13: 11125.2 | H13: 14915.6 | I13: 23289.2 | J13: 32482.4 | K13: 31139.4 | L13: 40755.1 | M13: 49766.9 | N13: 61988 | O13: 68720 | P13: 74643.2 | Q13: 107591.4 | R13: 100403.65 | S13: 107531.14 | T13: 128660.75 | U13: 136924.61 | V13: 133017.8 | W13: 122778.5 | X13: 138126.7 | Y13: 177850.3 | Z13: 209777
A14: Ивановская область | B14: 1282.1 | C14: 1371.9 | D14: 1638.1 | E14: 2245.5 | F14: 3164.4 | G14: 3620 | H14: 6900.4 | I14: 10403.7 | J14: 12064.7 | K14: 15007.8 | L14: 12800.8 | M14: 16221.5 | N14: 16234.7 | O14: 18578.8 | P14: 20923 | Q14: 21859.1 | R14: 20848.696 | S14: 27843.498 | T14: 31998.421 | U14: 40053.674 | V14: 43805.1 | W14: 52942.4 | X14: 59798 | Y14: 68921.5 | Z14: 53529.8
A15: Калужская область | B15: 2556.5 | C15: 3231.4 | D15: 3745.2 | E15: 4375.5 | F15: 5917.9 | G15: 7622.6 | H15: 10933.6 | I15: 15433.7 | J15: 24283.7 | K15: 23378.8 | L15: 26812.4 | M15: 33775.3 | N15: 42733.8 | O15: 42436.3 | P15: 44969.3 | Q15: 59763 | R15: 53878.887 | S15: 66936.244 | T15: 67997.41 | U15: 67111.999 | V15: 74857 | W15: 77177.3 | X15: 81566.1 | Y15: 94653.2 | Z15: 90512.8
A16: Костромская область | B16: 1758.5 | C16: 1730.4 | D16: 2446.8 | E16: 2901.3 | F16: 2885.2 | G16: 3916 | H16: 5327.9 | I16: 7991.2 | J16: 9680.4 | K16: 8416.9 | L16: 8960.5 | M16: 8045.9 | N16: 8485.2 | O16: 8307.4 | P16: 8663.1 | Q16: 13498.7 | R16: 10949.745 | S16: 9020.1356 | T16: 11780.177 | U16: 12591.934 | V16: 16057.8 | W16: 16885.5 | X16: 21026.2 | Y16: 22770.4 | Z16: 17111.1
A17: Курская область | B17: 2202.3 | C17: 3325.4 | D17: 3298.8 | E17: 4372.5 | F17: 6041.2 | G17: 7125.6 | H17: 10257.2 | I17: 14665.9 | J17: 20444.9 | K17: 19970 | L17: 23305.9 | M17: 29581.8 | N17: 33648.1 | O17: 36918.3 | P17: 42060.5 | Q17: 43495.9 | R17: 44911.462 | S17: 50200.474 | T17: 57125.95 | U17: 77081.02 | V17: 82453 | W17: 112268 | X17: 148635.8 | Y17: 176490 | Z17: 212428.8
A18: Липецкая область | B18: 2945.4 | C18: 3213.4 | D18: 3692.2 | E18: 5372.7 | F18: 8009.5 | G18: 12255.4 | H18: 15182.2 | I18: 19994 | J18: 23378.1 | K18: 25591.1 | L18: 25716.5 | M18: 28464.8 | N18: 31372.2 | O18: 34266.8 | P18: 36690.4 | Q18: 40838 | R18: 42387.857 | S18: 48597.179 | T18: 56015.196 | U18: 67817.606 | V18: 77019.9 | W18: 75787 | X18: 91059 | Y18: 105405 | Z18: 153180.1
A19: Московская область | B19: 21675.1 | C19: 30301.8 | D19: 33301.7 | E19: 41590 | F19: 74889.8 | G19: 120237.3 | H19: 161798.9 | I19: 217631.9 | J19: 271169.1 | K19: 210355.6 | L19: 230771.3 | M19: 265066 | N19: 303071.6 | O19: 289351.4 | P19: 314325.8 | Q19: 320716.2 | R19: 328467.97 | S19: 357555.05 | T19: 469584.01 | U19: 520116.58 | V19: 572893.8 | W19: 536546.2 | X19: 712509.4 | Y19: 719436.6 | Z19: 745700.9
A20: Орловская область | B20: 2219.7 | C20: 2832.3 | D20: 2676.5 | E20: 3352.1 | F20: 3827.2 | G20: 4255.2 | H20: 5796 | I20: 7981.4 | J20: 10923.4 | K20: 7988.3 | L20: 7859.7 | M20: 9497.9 | N20: 14687 | O20: 15796.6 | P20: 16861.4 | Q20: 23677.4 | R20: 19544.067 | S20: 21215.076 | T20: 22747.385 | U20: 27027.476 | V20: 29405.8 | W20: 32846.1 | X20: 35517.4 | Y20: 38655.9 | Z20: 36415.6
A21: Рязанская область | B21: 2565.8 | C21: 3928.2 | D21: 3983.2 | E21: 6488.8 | F21: 7804.6 | G21: 12164.9 | H21: 13986.3 | I21: 22072 | J21: 28061.5 | K21: 18685.1 | L21: 25768.3 | M21: 31881.5 | N21: 36509.6 | O21: 42200.2 | P21: 33091.2 | Q21: 43439.9 | R21: 40195.739 | S21: 45602.227 | T21: 49224.85 | U21: 54701.751 | V21: 50453.6 | W21: 54902.3 | X21: 61546.4 | Y21: 74586.5 | Z21: 93654.1
... A27: г. Москва | B27: 79814.7 | C27: 106552.6 | D27: 126584.5 | E27: 174140.3 | F27: 208219 | G27: 252215.5 | H27: 364844.8 | I27: 468172.7 | J27: 597413.4 | K27: 522941.7 | L27: 553874.9 | M27: 549075.8 | N27: 609729.3 | O27: 674276.8 | P27: 734697.6 | Q27: 806215.3 | R27: 876768.55 | S27: 911097.39 | T27: 915569.76 | U27: 951428.01 | V27: 1094815.1 | W27: 1311162.6 | X27: 1606165.4 | Y27: 1879125.4 | Z27: 1975923.2
A28: Северо-Западный федеральный округ | B28: =B29+B30+B31+B35+B36+B37+B38+B39+B40+B41 -> 52281.2 | C28: =C29+C30+C31+C35+C36+C37+C38+C39+C40+C41 -> 69913.3 | D28: =D29+D30+D31+D35+D36+D37+D38+D39+D40+D41 -> 90753.3 | E28: =E29+E30+E31+E35+E36+E37+E38+E39+E40+E41 -> 126037 | F28: =F29+F30+F31+F35+F36+F37+F38+F39+F40+F41 -> 159533.1 | G28: 229684.3 | H28: 360459.1 | I28: 451384.6 | J28: 630934 | K28: 587744.3 | L28: 679920.5 | M28: 730884.9 | N28: 783443.9 | O28: 771037.2 | P28: 817509.7 | Q28: 1048125.7 | R28: 1154849.1 | S28: 1067078.7 | T28: 1198579.1 | U28: 1164599.8 | V28: 1122401.8 | W28: 1250155.7 | X28: 1323868.6 | Y28: 1493897.5 | Z28: 1682760.6
A29: Республика Карелия | B29: 2213.5 | C29: 4055.2 | D29: 3994.4 | E29: 3812.4 | F29: 3827.4 | G29: 4892.8 | H29: 6222.2 | I29: 7395.5 | J29: 9729.1 | K29: 8457.5 | L29: 12343 | M29: 10910.7 | N29: 12182.6 | O29: 16459.2 | P29: 14003.3 | Q29: 19128.9 | R29: 16957.151 | S29: 21720.475 | T29: 31662.457 | U29: 30041.047 | V29: 28171.6 | W29: 31332.8 | X29: 46255.1 | Y29: 58437.4 | Z29: 40997.7
A30: Республика Коми | B30: 4764 | C30: 7851.1 | D30: 8651.9 | E30: 10805.9 | F30: 13395.5 | G30: 22773.8 | H30: 34669 | I30: 34517.5 | J30: 41550.9 | K30: 45628.6 | L30: 56608.9 | M30: 67662 | N30: 104123 | O30: 92221.8 | P30: 81184 | Q30: 77330.4 | R30: 105320.83 | S30: 45160.658 | T30: 47645.959 | U30: 44864.695 | V30: 60036.7 | W30: 54314.5 | X30: 50010.9 | Y30: 47221.4 | Z30: 57443
A31: Архангельская область | B31: 3895.1 | C31: 5795.9 | D31: 7494.1 | E31: 8065.4 | F31: 12210.1 | G31: 23218.4 | H31: 37479.1 | I31: 39707.1 | J31: 39780.8 | K31: 22279.7 | L31: 32936.5 | M31: 39207.5 | N31: 35476.1 | O31: 52319.9 | P31: 39997.6 | Q31: 45903.8 | R31: 56707.304 | S31: 71549.198 | T31: 95862.17 | U31: 84314.166 | V31: 71182.2 | W31: 105934 | X31: 88112.1 | Y31: 105098.3 | Z31: 72654.5
A32: в том числе:
A33: Ненецкий автономный округ | B33: 588.9 | C33: 2368.1 | D33: 4816.8 | E33: 3821.4 | F33: 6224.9 | G33: 8893.5 | H33: 12203.5 | I33: 25013.1 | J33: 12831.7 | K33: 6798.1 | L33: 11264.8 | M33: 11883.5 | N33: 6285.3 | O33: 8392.9 | P33: 8574.3 | Q33: 9962.1 | R33: 8720.189 | S33: 12207.72 | T33: 40650.263 | U33: 25996.494 | V33: 20479.5 | W33: 20724.6 | X33: 24326.2 | Y33: 18896 | Z33: 16878.1
A34: Архангельская область без автономного округа | B34: =B31-B33 -> 3306.2 | C34: =C31-C33 -> 3427.8 | D34: =D31-D33 -> 2677.3 | E34: =E31-E33 -> 4244 | F34: =F31-F33 -> 5985.2 | G34: 14324.9 | H34: =H31-H33 -> 25275.6 | I34: =I31-I33 -> 14694 | J34: =J31-J33 -> 26949.1 | K34: =K31-K33 -> 15481.6 | L34: 21671.7 | M34: 27324 | N34: 29190.8 | O34: 43927 | P34: 31423.3 | Q34: 35941.7 | R34: 47987.115 | S34: 59341.478 | T34: 55211.907 | U34: 58317.672 | V34: 50702.7 | W34: 85209.4 | X34: 63785.8 | Y34: 86202.4 | Z34: 55776.4
A35: Вологодская область | B35: 3965.1 | C35: 4928.6 | D35: 5697.5 | E35: 7642.5 | F35: 15893.5 | G35: 20027.2 | H35: 40069.4 | I35: 38736.3 | J35: 38044 | K35: 27674.1 | L35: 36395.3 | M35: 59683.7 | N35: 60476 | O35: 48862.7 | P35: 41429.5 | Q35: 55677.4 | R35: 65769.22 | S35: 91882.668 | T35: 103048.71 | U35: 108657.06 | V35: 115156.5 | W35: 124610.1 | X35: 107913.6 | Y35: 118600.1 | Z35: 138321.9
A36: Калининградская область | B36: 1694.2 | C36: 2158.4 | D36: 4960 | E36: 7712.3 | F36: 6749.7 | G36: 9582.3 | H36: 19011.3 | I36: 20650.5 | J36: 23583 | K36: 24900 | L36: 26470.9 | M36: 33681.6 | N36: 30994.3 | O36: 34604.3 | P36: 42045.3 | Q36: 59929.7 | R36: 72170.636 | S36: 98824.836 | T36: 105781.64 | U36: 71888.459 | V36: 82119.6 | W36: 73798.8 | X36: 88119.9 | Y36: 124198.9 | Z36: 141697.8
A37: Ленинградская область | B37: 7256.8 | C37: 8769 | D37: 8597.6 | E37: 17839.3 | F37: 22952.7 | G37: 27258.2 | H37: 53727 | I37: 58188.1 | J37: 77937.8 | K37: 80035.8 | L37: 89104.6 | M37: 102960.4 | N37: 114638.5 | O37: 90300.2 | P37: 101123.1 | Q37: 104491.5 | R37: 98149.98 | S37: 112532.39 | T37: 159227.24 | U37: 250991.98 | V37: 206423.6 | W37: 228443.1 | X37: 230365.5 | Y37: 270258.5 | Z37: 404458.8
A38: Мурманская область | B38: 2860.9 | C38: 4279.9 | D38: 4665.1 | E38: 5176.4 | F38: 6872.5 | G38: 9483.9 | H38: 10465.3 | I38: 12631.7 | J38: 16696 | K38: 16233.6 | L38: 18356.9 | M38: 21409.2 | N38: 22255.2 | O38: 22762.6 | P38: 28553.5 | Q38: 34009 | R38: 34379.239 | S38: 45332.975 | T38: 37883.21 | U38: 60734.412 | V38: 77052.6 | W38: 116664.2 | X38: 139008.5 | Y38: 118526.8 | Z38: 96957.8
A39: Новгородская область | B39: 2064.7 | C39: 3140.4 | D39: 2013 | E39: 4803.8 | F39: 5034.3 | G39: 6515.3 | H39: 7022.1 | I39: 9373.1 | J39: 12595.9 | K39: 15297 | L39: 17501.3 | M39: 17941.7 | N39: 21458.2 | O39: 26101.8 | P39: 34782.9 | Q39: 41877.7 | R39: 58217.463 | S39: 37323.982 | T39: 25952.076 | U39: 15048.915 | V39: 18572.2 | W39: 22239.7 | X39: 33840.4 | Y39: 40369.2 | Z39: 41739.8
A40: Псковская область | B40: 1583.2 | C40: 1719.4 | D40: 1910.3 | E40: 2782 | F40: 3265 | G40: 3915.2 | H40: 4033.5 | I40: 6872.1 | J40: 9232.8 | K40: 6621.7 | L40: 9192.7 | M40: 9912.6 | N40: 9968 | O40: 11601.3 | P40: 12705.5 | Q40: 17435.7 | R40: 21101.264 | S40: 25274.367 | T40: 26727.945 | U40: 28787.592 | V40: 24760.3 | W40: 24368.7 | X40: 31712.3 | Y40: 32809.2 | Z40: 32908.3
A41: г. Санкт-Петербург | B41: 21983.7 | C41: 27215.4 | D41: 42769.4 | E41: 57397 | F41: 69332.4 | G41: 102017.1 | H41: 147760.2 | I41: 223312.8 | J41: 361783.8 | K41: 340616.2 | L41: 381010.3 | M41: 367515.4 | N41: 371872 | O41: 375803.6 | P41: 421685.1 | Q41: 592341.5 | R41: 626076 | S41: 517477.19 | T41: 564787.64 | U41: 469271.52 | V41: 438926.5 | W41: 468449.8 | X41: 508530.3 | Y41: 578377.8 | Z41: 655581.1
A42: Южный федеральный округ | B42: =B43+B44+B46+B47+B48+B49 -> 43542.6 | C42: =C43+C44+C46+C47+C48+C49 -> 60275.1 | D42: =D43+D44+D46+D47+D48+D49 -> 74145 | E42: =E43+E44+E46+E47+E48+E49 -> 80427.5 | F42: =F43+F44+F46+F47+F48+F49 -> 94313.4 | G42: 123158 | H42: 172844.6 | I42: 246139.1 | J42: 357476.7 | K42: 347263.5 | L42: 449688.2 | M42: 561058.9 | N42: 628863 | O42: 731522.8 | P42: 587574.9 | Q42: 598496.4 | R42: 563542.84 | S42: 688675.6 | T42: 757941.48 | U42: 734512.76 | V42: 762653.5 | W42: 850913.8 | X42: 1004332 | Y42: 1176739.1 | Z42: 1351268.3
A43: Республика Адыгея | B43: 667.2 | C43: 862.7 | D43: 886.9 | E43: 1176.8 | F43: 1095.8 | G43: 1584.4 | H43: 1842.1 | I43: 6901.3 | J43: 6539 | K43: 7801 | L43: 7762.4 | M43: 9248.4 | N43: 9864.2 | O43: 9651.6 | P43: 10280.1 | Q43: 11545.8 | R43: 12867.982 | S43: 12704.382 | T43: 19453.974 | U43: 25473.07 | V43: 22669 | W43: 22338.5 | X43: 30605.6 | Y43: 34188.7 | Z43: 27888.7
A44: Республика Калмыкия | B44: 618.5 | C44: 1566 | D44: 2671.6 | E44: 1324.5 | F44: 1527.5 | G44: 1912.1 | H44: 2211.3 | I44: 1955 | J44: 2362.4 | K44: 2862 | L44: 2937.8 | M44: 2891.6 | N44: 3604.1 | O44: 3862.8 | P44: 8124 | Q44: 3525.6 | R44: 1320.821 | S44: 2945.5378 | T44: 6495.092 | U44: 7418.199 | V44: 8748.3 | W44: 4713.3 | X44: 7928.8 | Y44: 8646.1 | Z44: 10868.1
A45: Республика Крым | P45: 3208.7 | Q45: 3351.2 | R45: 16019.58 | S45: 51085.767 | T45: 151953.83 | U45: 138846.63 | V45: 142865.9 | W45: 102472.7 | X45: 138706.8 | Y45: 157448 | Z45: 125676.5
A46: Краснодарский край | B46: 22114.2 | C46: 30738.7 | D46: 38269.7 | E46: 40132.5 | F46: 49290.8 | G46: 57818.6 | H46: 84984 | I46: 125265.9 | J46: 182312.9 | K46: 204427.5 | L46: 299575.2 | M46: 399396.9 | N46: 442396.7 | O46: 480663.6 | P46: 316186.5 | Q46: 275549.8 | R46: 252093.37 | S46: 308669.28 | T46: 311056.06 | U46: 280753.72 | V46: 293715.7 | W46: 325673.7 | X46: 377375.1 | Y46: 431504.8 | Z46: 554811.4
...

Sheet 14.2.1.
A2: Социально-экономические показатели по субъектам Российской Федерации
A3: 14. СТРОИТЕЛЬСТВО
A4: СТРОИТЕЛЬНАЯ ДЕЯТЕЛЬНОСТЬ
A5: 14.2. ВВОД В ДЕЙСТВИЕ ЗДАНИЙ ЖИЛОГО И НЕЖИЛОГО НАЗНАЧЕНИЯ
A6: 14.2.1. Число зданий
B7: 2000 | C7: 2001 | D7: 2002 | E7: 2003 | F7: 2004 | G7: 2005 | H7: 2006 | I7: 2007 | J7: 2008 | K7: 2009 | L7: 2010 | M7: 2011 | N7: 2012 | O7: 2013 | P7: 2014 | Q7: 2015 | R7: 2016 | S7: 2017 | T7: 2018 | U7: 2019 | V7: 2020 | W7: 2021 | X7: 2022 | Y7: 2023 | Z7: 2024
A8: Российская Федерация | B8: 119750 | C8: 124976 | D8: 130789 | E8: 132494 | F8: 132014 | G8: 141619 | H8: 159033 | I8: 209893 | J8: 224634 | K8: 233319 | L8: 216540 | M8: 227242 | N8: 241424 | O8: 258119 | P8: 304194 | Q8: 306391 | R8: 278295 | S8: 272615 | T8: 261132 | U8: 305492 | V8: 326703 | W8: 403112 | X8: 434062 | Y8: 465458 | Z8: 496721
A9: Центральный федеральный округ | B9: 25795 | C9: 25704 | D9: 27375 | E9: 29199 | F9: 30975 | G9: 32968 | H9: 34443 | I9: 47477 | J9: 46872 | K9: 50131 | L9: 46174 | M9: 48836 | N9: 50411 | O9: 53498 | P9: 58180 | Q9: 72299 | R9: 64967 | S9: 69872 | T9: 69381 | U9: 81254 | V9: 87816 | W9: 107897 | X9: 123811 | Y9: 120867 | Z9: 118695
A10: Белгородская область | B10: 2983 | C10: 3200 | D10: 2807 | E10: 2964 | F10: 3184 | G10: 3804 | H10: 5097 | I10: 5951 | J10: 6172 | K10: 6800 | L10: 6937 | M10: 7778 | N10: 8494 | O10: 7961 | P10: 8773 | Q10: 10183 | R10: 9537 | S10: 8656 | T10: 8183 | U10: 9028 | V10: 7455 | W10: 8549 | X10: 5658 | Y10: 5449 | Z10: 5556
A11: Брянская область | B11: 850 | C11: 1224 | D11: 1096 | E11: 882 | F11: 879 | G11: 877 | H11: 842 | I11: 1050 | J11: 860 | K11: 933 | L11: 1021 | M11: 1018 | N11: 1048 | O11: 1968 | P11: 1658 | Q11: 1892 | R11: 975 | S11: 724 | T11: 725 | U11: 1168 | V11: 1436 | W11: 2095 | X11: 1776 | Y11: 1703 | Z11: 2133
A12: Владимирская область | B12: 1013 | C12: 1011 | D12: 1128 | E12: 1182 | F12: 1294 | G12: 1323 | H12: 1355 | I12: 1785 | J12: 1942 | K12: 2037 | L12: 2275 | M12: 1992 | N12: 2421 | O12: 2066 | P12: 2427 | Q12: 2658 | R12: 2545 | S12: 3114 | T12: 2529 | U12: 3355 | V12: 2985 | W12: 5000 | X12: 4711 | Y12: 5016 | Z12: 5553
A13: Воронежская область | B13: 1815 | C13: 2029 | D13: 2297 | E13: 1902 | F13: 1694 | G13: 1583 | H13: 1513 | I13: 1797 | J13: 2210 | K13: 2515 | L13: 2508 | M13: 2623 | N13: 2984 | O13: 3725 | P13: 3772 | Q13: 3401 | R13: 3241 | S13: 3999 | T13: 4975 | U13: 5182 | V13: 5531 | W13: 7735 | X13: 6813 | Y13: 7008 | Z13: 9339
A14: Ивановская область | B14: 337 | C14: 348 | D14: 404 | E14: 371 | F14: 417 | G14: 341 | H14: 389 | I14: 411 | J14: 492 | K14: 584 | L14: 507 | M14: 669 | N14: 631 | O14: 616 | P14: 615 | Q14: 535 | R14: 317 | S14: 835 | T14: 940 | U14: 1186 | V14: 1368 | W14: 1953 | X14: 1492 | Y14: 1835 | Z14: 1876
A15: Калужская область | B15: 716 | C15: 900 | D15: 918 | E15: 1201 | F15: 1168 | G15: 1390 | H15: 1332 | I15: 2100 | J15: 3764 | K15: 2828 | L15: 2742 | M15: 3043 | N15: 2838 | O15: 3310 | P15: 4214 | Q15: 3593 | R15: 3349 | S15: 3860 | T15: 3334 | U15: 3832 | V15: 5298 | W15: 4968 | X15: 5214 | Y15: 6392 | Z15: 5991
A16: Костромская область | B16: 389 | C16: 461 | D16: 438 | E16: 461 | F16: 497 | G16: 576 | H16: 439 | I16: 605 | J16: 688 | K16: 769 | L16: 582 | M16: 573 | N16: 612 | O16: 1527 | P16: 1650 | Q16: 1470 | R16: 1742 | S16: 1105 | T16: 1019 | U16: 1116 | V16: 1013 | W16: 1426 | X16: 1437 | Y16: 1509 | Z16: 1706
A17: Курская область | B17: 630 | C17: 664 | D17: 656 | E17: 683 | F17: 876 | G17: 756 | H17: 599 | I17: 688 | J17: 896 | K17: 861 | L17: 701 | M17: 894 | N17: 1279 | O17: 1627 | P17: 1493 | Q17: 1972 | R17: 2009 | S17: 1995 | T17: 2539 | U17: 2760 | V17: 2891 | W17: 2780 | X17: 2693 | Y17: 2740 | Z17: 3160
A18: Липецкая область | B18: 1329 | C18: 1520 | D18: 1273 | E18: 1276 | F18: 1388 | G18: 1535 | H18: 2149 | I18: 2723 | J18: 2404 | K18: 2553 | L18: 2655 | M18: 2332 | N18: 2726 | O18: 2973 | P18: 3301 | Q18: 3118 | R18: 3558 | S18: 4795 | T18: 4089 | U18: 5454 | V18: 7066 | W18: 6297 | X18: 3445 | Y18: 3770 | Z18: 3665
A19: Московская область | B19: 8719 | C19: 7279 | D19: 8456 | E19: 10092 | F19: 11524 | G19: 12645 | H19: 12215 | I19: 19994 | J19: 17569 | K19: 19167 | L19: 16351 | M19: 15707 | N19: 14080 | O19: 10825 | P19: 11445 | Q19: 22627 | R19: 18919 | S19: 22452 | T19: 22918 | U19: 25505 | V19: 32160 | W19: 42044 | X19: 64694 | Y19: 56426 | Z19: 51014
... A31: Архангельская область | B31: 452 | C31: 539 | D31: 587 | E31: 586 | F31: 502 | G31: 627 | H31: 588 | I31: 1065 | J31: 1468 | K31: 1593 | L31: 1466 | M31: 1786 | N31: 1832 | O31: 1460 | P31: 1777 | Q31: 1726 | R31: 1717 | S31: 1634 | T31: 1599 | U31: 1419 | V31: 1818 | W31: 1982 | X31: 2082 | Y31: 1948 | Z31: 1902
A32: в том числе:
A33: Ненецкий автономный округ | B33: 43 | C33: 26 | D33: 29 | E33: 31 | F33: 14 | G33: 77 | H33: 100 | I33: 91 | J33: 179 | K33: 112 | L33: 126 | M33: 133 | N33: 130 | O33: 124 | P33: 104 | Q33: 98 | R33: 121 | S33: 115 | T33: 87 | U33: 63 | V33: 94 | W33: 87 | X33: 152 | Y33: 158 | Z33: 121
A34: Архангельская область без автономного округа | B34: 409 | C34: =C31-C33 -> 513 | D34: =D31-D33 -> 558 | E34: =E31-E33 -> 555 | F34: 488 | G34: 550 | H34: 488 | I34: 974 | J34: 1289 | K34: 1481 | L34: 1340 | M34: 1653 | N34: 1702 | O34: 1336 | P34: 1673 | Q34: 1628 | R34: 1596 | S34: 1519 | T34: 1512 | U34: 1356 | V34: 1724 | W34: 1895 | X34: 1930 | Y34: 1790 | Z34: 1781
A35: Вологодская область | B35: 961 | C35: 1051 | D35: 1110 | E35: 1034 | F35: 1046 | G35: 1230 | H35: 1105 | I35: 1765 | J35: 2090 | K35: 2121 | L35: 1905 | M35: 2053 | N35: 1857 | O35: 4779 | P35: 6527 | Q35: 6182 | R35: 3849 | S35: 2172 | T35: 2560 | U35: 3142 | V35: 2488 | W35: 3486 | X35: 3623 | Y35: 4199 | Z35: 4176
A36: Калининградская область | B36: 334 | C36: 352 | D36: 403 | E36: 550 | F36: 500 | G36: 553 | H36: 573 | I36: 1352 | J36: 1380 | K36: 1063 | L36: 720 | M36: 789 | N36: 842 | O36: 1370 | P36: 3109 | Q36: 2773 | R36: 2494 | S36: 1744 | T36: 1722 | U36: 2140 | V36: 3043 | W36: 4164 | X36: 4367 | Y36: 4384 | Z36: 4964
A37: Ленинградская область | B37: 1966 | C37: 2053 | D37: 2382 | E37: 2776 | F37: 2751 | G37: 3136 | H37: 3061 | I37: 5109 | J37: 5261 | K37: 5826 | L37: 4285 | M37: 4794 | N37: 5269 | O37: 4647 | P37: 6989 | Q37: 6794 | R37: 5462 | S37: 5856 | T37: 6737 | U37: 10317 | V37: 13279 | W37: 17403 | X37: 19390 | Y37: 19274 | Z37: 21384
A38: Мурманская область | B38: 108 | C38: 294 | D38: 127 | E38: 133 | F38: 147 | G38: 186 | H38: 108 | I38: 191 | J38: 142 | K38: 116 | L38: 74 | M38: 168 | N38: 97 | O38: 96 | P38: 169 | Q38: 175 | R38: 213 | S38: 240 | T38: 334 | U38: 434 | V38: 364 | W38: 454 | X38: 492 | Y38: 535 | Z38: 626
A39: Новгородская область | B39: 725 | C39: 703 | D39: 779 | E39: 754 | F39: 859 | G39: 796 | H39: 756 | I39: 948 | J39: 1144 | K39: 1566 | L39: 1693 | M39: 1604 | N39: 1962 | O39: 1709 | P39: 1994 | Q39: 1999 | R39: 1596 | S39: 1220 | T39: 1430 | U39: 1762 | V39: 1723 | W39: 2015 | X39: 2078 | Y39: 2517 | Z39: 2067
A40: Псковская область | B40: 436 | C40: 433 | D40: 501 | E40: 487 | F40: 499 | G40: 482 | H40: 417 | I40: 615 | J40: 665 | K40: 890 | L40: 647 | M40: 649 | N40: 972 | O40: 996 | P40: 1955 | Q40: 1757 | R40: 1436 | S40: 1106 | T40: 1047 | U40: 2205 | V40: 1689 | W40: 2250 | X40: 1760 | Y40: 2084 | Z40: 2105
A41: г. Санкт-Петербург | B41: 425 | C41: 628 | D41: 576 | E41: 769 | F41: 590 | G41: 631 | H41: 590 | I41: 1381 | J41: 1495 | K41: 1873 | L41: 1044 | M41: 952 | N41: 888 | O41: 1296 | P41: 2334 | Q41: 1871 | R41: 1631 | S41: 1317 | T41: 2189 | U41: 1887 | V41: 1488 | W41: 1702 | X41: 1642 | Y41: 1559 | Z41: 1213
A42: Южный федеральный округ | B42: 19334 | C42: 20381 | D42: 22696 | E42: 19359 | F42: 19394 | G42: 20120 | H42: 23966 | I42: 32762 | J42: 34493 | K42: 34258 | L42: 31336 | M42: 33124 | N42: 35893 | O42: 35862 | P42: 40952 | Q42: 39302 | R42: 35093 | S42: 36618 | T42: 34643 | U42: 42342 | V42: 44510 | W42: 57126 | X42: 64690 | Y42: 71417 | Z42: 69257
A43: Республика Адыгея | B43: 487 | C43: 525 | D43: 1149 | E43: 606 | F43: 347 | G43: 393 | H43: 299 | I43: 302 | J43: 493 | K43: 878 | L43: 837 | M43: 800 | N43: 689 | O43: 693 | P43: 1198 | Q43: 1033 | R43: 1076 | S43: 961 | T43: 756 | U43: 1082 | V43: 1268 | W43: 1619 | X43: 2381 | Y43: 3030 | Z43: 2887
A44: Республика Калмыкия | B44: 240 | C44: 524 | D44: 432 | E44: 402 | F44: 342 | G44: 303 | H44: 472 | I44: 747 | J44: 539 | K44: 589 | L44: 507 | M44: 538 | N44: 429 | O44: 462 | P44: 474 | Q44: 439 | R44: 248 | S44: 570 | T44: 579 | U44: 666 | V44: 573 | W44: 906 | X44: 899 | Y44: 877 | Z44: 907
A45: Республика Крым | P45: 1548 | Q45: 723 | R45: 475 | S45: 3842 | T45: 2666 | U45: 4118 | V45: 4624 | W45: 3598 | X45: 5166 | Y45: 7119 | Z45: 8178
A46: Краснодарский край | B46: 8558 | C46: 8925 | D46: 10644 | E46: 8720 | F46: 9236 | G46: 9476 | H46: 11823 | I46: 17725 | J46: 18453 | K46: 17084 | L46: 14631 | M46: 15129 | N46: 15618 | O46: 16748 | P46: 17918 | Q46: 16151 | R46: 14636 | S46: 13688 | T46: 14640 | U46: 17202 | V46: 18225 | W46: 28892 | X46: 35891 | Y46: 36968 | Z46: 32704
A47: Астраханская область | B47: 1861 | C47: 2297 | D47: 1973 | E47: 1822 | F47: 1721 | G47: 2365 | H47: 2979 | I47: 2011 | J47: 1357 | K47: 1505 | L47: 1729 | M47: 2322 | N47: 2846 | O47: 2354 | P47: 2792 | Q47: 3139 | R47: 3716 | S47: 2519 | T47: 2179 | U47: 2219 | V47: 2729 | W47: 3558 | X47: 3439 | Y47: 3903 | Z47: 3766
A48: Волгоградская область | B48: 1859 | C48: 1925 | D48: 1954 | E48: 1816 | F48: 1581 | G48: 1376 | H48: 1809 | I48: 3269 | J48: 3497 | K48: 3372 | L48: 2720 | M48: 2856 | N48: 4538 | O48: 3912 | P48: 5549 | Q48: 3798 | R48: 3064 | S48: 2822 | T48: 2483 | U48: 3235 | V48: 2976 | W48: 3402 | X48: 3753 | Y48: 3826 | Z48: 4535
A49: Ростовская область | B49: 6329 | C49: 6185 | D49: 6544 | E49: 5993 | F49: 6167 | G49: 6207 | H49: 6584 | I49: 8708 | J49: 10154 | K49: 10830 | L49: 10912 | M49: 11479 | N49: 11773 | O49: 11693 | P49: 11403 | Q49: 13984 | R49: 11824 | S49: 11858 | T49: 10104 | U49: 10407 | V49: 10286 | W49: 11596 | X49: 9975 | Y49: 12479 | Z49: 14024
A50: г. Севастополь | P50: 70 | Q50: 35 | R50: 54 | S50: 358 | T50: 1236 | U50: 3413 | V50: 3829 | W50: 3555 | X50: 3186 | Y50: 3215 | Z50: 2256
A51: Северо-Кавказский федеральный округ | B51: 10189 | C51: 11758 | D51: 11111 | E51: 11710 | F51: 11208 | G51: 11567 | H51: 11445 | I51: 14785 | J51: 14548 | K51: 14846 | L51: 15760 | M51: 15026 | N51: 19647 | O51: 18699 | P51: 28869 | Q51: 26025 | R51: 25838 | S51: 21931 | T51: 15264 | U51: 16608 | V51: 17740 | W51: 24033 | X51: 28873 | Y51: 35929 | Z51: 43522
A52: Республика Дагестан | B52: 3385 | C52: 4815 | D52: 3727 | E52: 4633 | F52: 4572 | G52: 4493 | H52: 4601 | I52: 5260 | J52: 5420 | K52: 6800 | L52: 7509 | M52: 7133 | N52: 8253 | O52: 6987 | P52: 7896 | Q52: 9108 | R52: 9362 | S52: 7892 | T52: 3598 | U52: 3655 | V52: 3096 | W52: 3213 | X52: 3427 | Y52: 7657 | Z52: 12477
...

Sheet 14.2.2.
A2: Социально-экономические показатели по субъектам Российской Федерации
A3: 14. СТРОИТЕЛЬСТВО
A4: СТРОИТЕЛЬНАЯ ДЕЯТЕЛЬНОСТЬ
A5: 14.2. ВВОД В ДЕЙСТВИЕ ЗДАНИЙ ЖИЛОГО И НЕЖИЛОГО НАЗНАЧЕНИЯ
A6: 14.2.2. Общая площадь зданий
A7: (тысяч квадратных метров)
B8: 2000 | C8: 2001 | D8: 2002 | E8: 2003 | F8: 2004 | G8: 2005 | H8: 2006 | I8: 2007 | J8: 2008 | K8: 2009 | L8: 2010 | M8: 2011 | N8: 2012 | O8: 2013 | P8: 2014 | Q8: 2015 | R8: 2016 | S8: 2017 | T8: 2018 | U8: 2019 | V8: 2020 | W8: 2021 | X8: 2022 | Y8: 2023 | Z8: 2024
A9: Российская Федерация | B9: 44673.6 | C9: 47650.5 | D9: 49589.4 | E9: 53715.4 | F9: 59949.5 | G9: 66289.1 | H9: 75553.7 | I9: 98068.6 | J9: 102516.7 | K9: 95056.5 | L9: 91454.1 | M9: 98982.5 | N9: 110376.7 | O9: 117785 | P9: 138614.2 | Q9: 139436.5 | R9: 135849.9 | S9: 137355.6 | T9: 132721.4 | U9: 146745.4 | V9: 143409.7 | W9: 148409.8 | X9: 160189.6 | Y9: 175042.2 | Z9: 170780.7
A10: Центральный федеральный округ | B10: 14298.9 | C10: 15293.9 | D10: 17216.7 | E10: 18643.6 | F10: 22257.9 | G10: 23020.7 | H10: 26054.5 | I10: 32862.6 | J10: 31934.2 | K10: 30386.5 | L10: 27105.1 | M10: 27866.2 | N10: 32329.7 | O10: 36639.8 | P10: 43204.3 | Q10: 42783.3 | R10: 44823.9 | S10: 45752.2 | T10: 42589.9 | U10: 48036.7 | V10: 47252.2 | W10: 51157.7 | X10: 53392.4 | Y10: 54630.5 | Z10: 50599.5
A11: Белгородская область | B11: 988.1 | C11: 899.7 | D11: 1119 | E11: 971 | F11: 1310 | G11: 1406.5 | H11: 1905.2 | I11: 2360.6 | J11: 2718.2 | K11: 2978.5 | L11: 2023.5 | M11: 1710.1 | N11: 2540.4 | O11: 2432 | P11: 2245.9 | Q11: 2307.5 | R11: 2638.8 | S11: 2468.6 | T11: 2089.9 | U11: 2036.2 | V11: 1669.1 | W11: 1452.5 | X11: 1211.7 | Y11: 1220.7 | Z11: 1094.4
A12: Брянская область | B12: 359.8 | C12: 334.3 | D12: 324.2 | E12: 298.5 | F12: 368.8 | G12: 266.1 | H12: 329.3 | I12: 406 | J12: 458.6 | K12: 520.9 | L12: 550.9 | M12: 740.8 | N12: 715.2 | O12: 916.9 | P12: 922 | Q12: 1146.7 | R12: 1114.2 | S12: 986.9 | T12: 728.7 | U12: 699.3 | V12: 1154.5 | W12: 1115.2 | X12: 1574.7 | Y12: 852.4 | Z12: 1015.5
A13: Владимирская область | B13: 380.5 | C13: 325 | D13: 356.2 | E13: 374.6 | F13: 420.5 | G13: 431.1 | H13: 570.1 | I13: 514.4 | J13: 677.6 | K13: 694.1 | L13: 679.3 | M13: 582.5 | N13: 739 | O13: 761 | P13: 920.1 | Q13: 900.7 | R13: 1067.7 | S13: 958.3 | T13: 965.8 | U13: 1112 | V13: 983.2 | W13: 1159.4 | X13: 1572.9 | Y13: 1477.5 | Z13: 1399.2
A14: Воронежская область | B14: 834.5 | C14: 822.1 | D14: 848.1 | E14: 1041.9 | F14: 910 | G14: 1056.6 | H14: 1125.9 | I14: 1482.1 | J14: 1704.9 | K14: 1392.4 | L14: 1568.4 | M14: 1568.6 | N14: 1786.6 | O14: 2156.5 | P14: 2629.7 | Q14: 2675.1 | R14: 2665.5 | S14: 3019.1 | T14: 2937.7 | U14: 2945.2 | V14: 3006 | W14: 2955.8 | X14: 3174.8 | Y14: 3353.7 | Z14: 3190.7
A15: Ивановская область | B15: 157.2 | C15: 107.2 | D15: 129.2 | E15: 183.9 | F15: 161.4 | G15: 153.4 | H15: 275.6 | I15: 221.6 | J15: 285.3 | K15: 411.9 | L15: 266.9 | M15: 384.4 | N15: 374.2 | O15: 489.5 | P15: 516.7 | Q15: 434.1 | R15: 345.2 | S15: 558.5 | T15: 546.5 | U15: 550.2 | V15: 612.5 | W15: 483.1 | X15: 631.7 | Y15: 692.2 | Z15: 674
A16: Калужская область | B16: 242.4 | C16: 287.6 | D16: 285.8 | E16: 398.4 | F16: 339.2 | G16: 415.4 | H16: 466.6 | I16: 765.9 | J16: 1010.1 | K16: 800.2 | L16: 1065.6 | M16: 960.2 | N16: 959.1 | O16: 948.1 | P16: 1372.8 | Q16: 1686.6 | R16: 1536.3 | S16: 1696.4 | T16: 1513.9 | U16: 1803.7 | V16: 1446.1 | W16: 1408 | X16: 1354 | Y16: 1656.8 | Z16: 1382.9
A17: Костромская область | B17: 203.4 | C17: 235.5 | D17: 162 | E17: 176.4 | F17: 210.5 | G17: 214.7 | H17: 321.7 | I17: 235 | J17: 228.1 | K17: 259.1 | L17: 248.4 | M17: 249.2 | N17: 249.6 | O17: 310.5 | P17: 418.7 | Q17: 469.9 | R17: 450.1 | S17: 405.2 | T17: 266.9 | U17: 313.1 | V17: 350.7 | W17: 458.8 | X17: 530.6 | Y17: 464.9 | Z17: 431.1
A18: Курская область | B18: 225.4 | C18: 281.6 | D18: 266.5 | E18: 388.4 | F18: 396.5 | G18: 538 | H18: 565.4 | I18: 667.3 | J18: 787.3 | K18: 794.9 | L18: 655.4 | M18: 827.5 | N18: 1275.7 | O18: 1130.4 | P18: 1395.4 | Q18: 1030.4 | R18: 1638.5 | S18: 1279.5 | T18: 1295 | U18: 1448.8 | V18: 1356.8 | W18: 2043.9 | X18: 917.6 | Y18: 1150.5 | Z18: 1076.8
A19: Липецкая область | B19: 461.7 | C19: 569 | D19: 450.2 | E19: 465.9 | F19: 640.9 | G19: 659.9 | H19: 984.8 | I19: 954.5 | J19: 1011.6 | K19: 954.2 | L19: 1032.8 | M19: 897.9 | N19: 1186.3 | O19: 1226.5 | P19: 1279 | Q19: 1678.1 | R19: 1718.2 | S19: 2041.1 | T19: 1378.4 | U19: 1908 | V19: 2200.5 | W19: 1897.5 | X19: 1128.5 | Y19: 1027.1 | Z19: 1250.5
A20: Московская область | B20: 3365.5 | C20: 3822 | D20: 4611.5 | E20: 5347.7 | F20: 7871.4 | G20: 7027.2 | H20: 8657.3 | I20: 12265 | J20: 12119.2 | K20: 11858.1 | L20: 11177.8 | M20: 11325.4 | N20: 9700.8 | O20: 11528.4 | P20: 16525.7 | Q20: 14421 | R20: 16686.2 | S20: 16461.9 | T20: 15465.5 | U20: 15751.9 | V20: 15924.7 | W20: 14823 | X20: 20910.3 | Y20: 19724.2 | Z20: 17952.5
... A32: Архангельская область | B32: 145.9 | C32: 152.7 | D32: 179.1 | E32: 178.6 | F32: 306.2 | G32: 199.8 | H32: 271 | I32: 396.3 | J32: 521.6 | K32: 404 | L32: 509.5 | M32: 463 | N32: 506.4 | O32: 599.8 | P32: 616.2 | Q32: 757.5 | R32: 644 | S32: 644.3 | T32: 617.3 | U32: 572.6 | V32: 552.2 | W32: 659.7 | X32: 724.2 | Y32: 668.9 | Z32: 681.8
A33: в том числе:
A34: Ненецкий автономный округ | B34: 31.4 | C34: 18 | D34: 12.3 | E34: 20.9 | F34: 6 | G34: 50.2 | H34: 43 | I34: 65.2 | J34: 121.4 | K34: 84.5 | L34: 92.5 | M34: 40.8 | N34: 51.6 | O34: 53.7 | P34: 50.2 | Q34: 59.5 | R34: 30 | S34: 57.9 | T34: 20.1 | U34: 13 | V34: 49.7 | W34: 28.2 | X34: 46.8 | Y34: 23.6 | Z34: 34.6
A35: Архангельская область без автономного округа | B35: 114.5 | C35: =C32-C34 -> 134.7 | D35: =D32-D34 -> 166.8 | E35: 157.7 | F35: 300.2 | G35: 149.6 | H35: 228 | I35: 331.1 | J35: 400.2 | K35: 319.5 | L35: 417 | M35: 422.2 | N35: 454.8 | O35: 546.1 | P35: 565.9 | Q35: 698 | R35: 614 | S35: 586.4 | T35: 597.2 | U35: 559.6 | V35: 502.5 | W35: 631.4 | X35: 677.4 | Y35: 645.3 | Z35: 647.2
A36: Вологодская область | B36: 357.4 | C36: 437.2 | D36: 356.9 | E36: 389.5 | F36: 337.6 | G36: 466.3 | H36: 579.5 | I36: 750 | J36: 830.8 | K36: 683.6 | L36: 628.4 | M36: 614.1 | N36: 565.1 | O36: 873.1 | P36: 1047.6 | Q36: 1088.4 | R36: 1029.4 | S36: 710.8 | T36: 778.7 | U36: 906.3 | V36: 682.7 | W36: 988.1 | X36: 962.5 | Y36: 1062.7 | Z36: 1109.7
A37: Калининградская область | B37: 234.6 | C37: 230.2 | D37: 271.4 | E37: 351.5 | F37: 396.3 | G37: 492.2 | H37: 696.6 | I37: 1011.7 | J37: 1064.6 | K37: 840.7 | L37: 753.9 | M37: 793.7 | N37: 857.5 | O37: 1038.4 | P37: 1412.1 | Q37: 1632.3 | R37: 1593.9 | S37: 1412 | T37: 1841.5 | U37: 1785.6 | V37: 2057.2 | W37: 1740 | X37: 1856.3 | Y37: 1765.1 | Z37: 1868.5
A38: Ленинградская область | B38: 596.5 | C38: 582 | D38: 741.2 | E38: 685.4 | F38: 769.7 | G38: 851.7 | H38: 1298.8 | I38: 1807.4 | J38: 1419.2 | K38: 1500.8 | L38: 1449.1 | M38: 1672.7 | N38: 2190.2 | O38: 2138.3 | P38: 3081.9 | Q38: 3467.7 | R38: 3374 | S38: 4489.1 | T38: 4841.7 | U38: 5078.8 | V38: 4808.1 | W38: 4659.1 | X38: 5547.8 | Y38: 6067.5 | Z38: 5589.4
A39: Мурманская область | B39: 122.8 | C39: 104.8 | D39: 56 | E39: 56.9 | F39: 49.7 | G39: 53.7 | H39: 70 | I39: 71.2 | J39: 90.7 | K39: 67.6 | L39: 89.8 | M39: 89.5 | N39: 66.7 | O39: 108.4 | P39: 128.9 | Q39: 190.1 | R39: 148 | S39: 787.5 | T39: 120.4 | U39: 172.3 | V39: 88.9 | W39: 162.1 | X39: 357.9 | Y39: 92.5 | Z39: 118
A40: Новгородская область | B40: 151.2 | C40: 142.6 | D40: 132.5 | E40: 144.9 | F40: 233.6 | G40: 157.6 | H40: 270.1 | I40: 296.5 | J40: 342.7 | K40: 422.5 | L40: 356.3 | M40: 438.7 | N40: 410.8 | O40: 460.4 | P40: 457.5 | Q40: 516.1 | R40: 502.8 | S40: 334.1 | T40: 406.6 | U40: 415.2 | V40: 412.4 | W40: 417.8 | X40: 437.6 | Y40: 520.6 | Z40: 531.8
A41: Псковская область | B41: 101.7 | C41: 111.4 | D41: 121.9 | E41: 150.3 | F41: 181.4 | G41: 138.6 | H41: 157.3 | I41: 175 | J41: 227.3 | K41: 314.8 | L41: 232 | M41: 313.9 | N41: 409.9 | O41: 328.2 | P41: 850.5 | Q41: 892.2 | R41: 649.8 | S41: 1677.6 | T41: 564.4 | U41: 829 | V41: 842.6 | W41: 599.2 | X41: 467.5 | Y41: 596.7 | Z41: 616.3
A42: г. Санкт-Петербург | B42: 1726.7 | C42: 1909.2 | D42: 1906.3 | E42: 2845.9 | F42: 3252.3 | G42: 3700.2 | H42: 4073.5 | I42: 5019.2 | J42: 6316 | K42: 4720.5 | L42: 5552.6 | M42: 5129.8 | N42: 4794 | O42: 5114.4 | P42: 6380.2 | Q42: 5411.6 | R42: 5794.8 | S42: 5182.3 | T42: 5963.4 | U42: 5776.7 | V42: 5484.9 | W42: 6741.7 | X42: 7691.4 | Y42: 7775 | Z42: 6932.6
A43: Южный федеральный округ | B43: 4421 | C43: 4493.4 | D43: 4757.3 | E43: 4989.3 | F43: 5772.4 | G43: 5981.2 | H43: 7698.1 | I43: 9847.7 | J43: 10563.2 | K43: 10013.7 | L43: 9481.8 | M43: 10781 | N43: 11658.4 | O43: 11261.2 | P43: 13813.9 | Q43: 13300.3 | R43: 13246.9 | S43: 13729.5 | T43: 14688.8 | U43: 17262.1 | V43: 16505.3 | W43: 17411.5 | X43: 19664 | Y43: 21772.6 | Z43: 20180.7
A44: Республика Адыгея | B44: 85.3 | C44: 102 | D44: 125.1 | E44: 82.4 | F44: 42.5 | G44: 92.8 | H44: 50.4 | I44: 75.5 | J44: 97.8 | K44: 232.1 | L44: 207.4 | M44: 234.6 | N44: 306.3 | O44: 218.7 | P44: 472.5 | Q44: 506.8 | R44: 422.2 | S44: 450.2 | T44: 306.6 | U44: 414 | V44: 382.5 | W44: 407.2 | X44: 640 | Y44: 755.4 | Z44: 748
A45: Республика Калмыкия | B45: 38.5 | C45: 90.6 | D45: 71 | E45: 62 | F45: 70.5 | G45: 62.2 | H45: 77 | I45: 114.3 | J45: 97.6 | K45: 96.8 | L45: 128.4 | M45: 129.5 | N45: 115.7 | O45: 162.2 | P45: 165.5 | Q45: 178 | R45: 89.2 | S45: 154.2 | T45: 128.5 | U45: 161.5 | V45: 134.1 | W45: 200.3 | X45: 172.2 | Y45: 189.9 | Z45: 177.4
A46: Республика Крым | P46: 890.5 | Q46: 321.4 | R46: 376 | S46: 1008 | T46: 1251.9 | U46: 1324.9 | V46: 1166.8 | W46: 1136.6 | X46: 1276.6 | Y46: 1800.1 | Z46: 1795.4
A47: Краснодарский край | B47: 1813 | C47: 1834.5 | D47: 2078.6 | E47: 2067.4 | F47: 2408.9 | G47: 2638.2 | H47: 3791 | I47: 4682.9 | J47: 5308.8 | K47: 4631.2 | L47: 4690.7 | M47: 5789.9 | N47: 6192.4 | O47: 5519.6 | P47: 6144.9 | Q47: 5876.9 | R47: 6223.9 | S47: 6173.9 | T47: 6721 | U47: 8355.9 | V47: 7947 | W47: 9001.3 | X47: 10850.9 | Y47: 11595 | Z47: 10357.8
A48: Астраханская область | B48: 572 | C48: 612.3 | D48: 648.2 | E48: 723.2 | F48: 715.7 | G48: 800.1 | H48: 796.4 | I48: 891.6 | J48: 504.4 | K48: 676.6 | L48: 765.6 | M48: 817.9 | N48: 671.4 | O48: 815.7 | P48: 800.5 | Q48: 776.4 | R48: 810.8 | S48: 738.7 | T48: 474.8 | U48: 491.3 | V48: 497 | W48: 675.8 | X48: 705 | Y48: 870.6 | Z48: 748.1
A49: Волгоградская область | B49: 557.5 | C49: 515.5 | D49: 533.2 | E49: 491.8 | F49: 597.1 | G49: 600.2 | H49: 797 | I49: 1010.9 | J49: 1263.8 | K49: 1128.8 | L49: 1058.7 | M49: 1025.1 | N49: 1392.1 | O49: 1387.8 | P49: 1660.5 | Q49: 1591.4 | R49: 1313.7 | S49: 1287.7 | T49: 1416.9 | U49: 1681.6 | V49: 1402.6 | W49: 1363.9 | X49: 1290 | Y49: 1582.3 | Z49: 1646
A50: Ростовская область | B50: 1354.7 | C50: 1338.5 | D50: 1301.2 | E50: 1562.5 | F50: 1937.7 | G50: 1787.7 | H50: 2186.3 | I50: 3072.5 | J50: 3290.8 | K50: 3248.2 | L50: 2631 | M50: 2783.9 | N50: 2980.4 | O50: 3157.2 | P50: 3327.2 | Q50: 3900.3 | R50: 3700.9 | S50: 3647.3 | T50: 4014.7 | U50: 4043.6 | V50: 4108.6 | W50: 3999 | X50: 4004.8 | Y50: 4306.9 | Z50: 4195.9
A51: г. Севастополь | P51: 352.3 | Q51: 149.1 | R51: 310.3 | S51: 269.6 | T51: 374.4 | U51: 789.3 | V51: 866.7 | W51: 627.3 | X51: 724.6 | Y51: 672.3 | Z51: 512.1
A52: Северо-Кавказский федеральный округ | B52: 2164.4 | C52: 2161.9 | D52: 2094.7 | E52: 2172.8 | F52: 2316.9 | G52: 3632 | H52: 2942.9 | I52: 3829.2 | J52: 3945.1 | K52: 4281.8 | L52: 4688.7 | M52: 4787.2 | N52: 6089.6 | O52: 5777.2 | P52: 7325.1 | Q52: 9992.3 | R52: 8493.4 | S52: 8309.4 | T52: 5768.9 | U52: 6770.4 | V52: 6697.1 | W52: 6856.2 | X52: 8274.6 | Y52: 10826.1 | Z52: 12372.7
...

Sheet 14.3.1.
A2: Социально-экономические показатели по субъектам Российской Федерации
A3: 14. СТРОИТЕЛЬСТВО
A4: ЖИЛИЩНОЕ И СОЦИАЛЬНО-КУЛЬТУРНОЕ СТРОИТЕЛЬСТВО
A5: 14.3. ВВОД В ДЕЙСТВИЕ ЖИЛЫХ ДОМОВ
A6: 14.3.1. Всего
A7: (тысяч квадратных метров общей площади жилых помещений)
B8: 2000 | C8: 2001 | D8: 2002 | E8: 2003 | F8: 2004 | G8: 2005 | H8: 2006 | I8: 2007 | J8: 2008 | K8: 2009 | L8: 2010 | M8: 2011 | N8: 2012 | O8: 2013 | P8: 2014 | Q8: 2015 | R8: 2016 | S8: 2017 | T8: 2018 | U8: 2019 | V8: 2020 | W8: 2021 | X8: 2022 | Y8: 2023 | Z8: 2024
A9: Российская Федерация | B9: 30295.8 | C9: 31703.2 | D9: 33832.2 | E9: 36449.3 | F9: 41040.1 | G9: 43559.5 | H9: 50552.1 | I9: 61221.3 | J9: 64058.4 | K9: 59891.6 | L9: 58430.7 | M9: 62264.6 | N9: 65741.51 | O9: 70484.9 | P9: 84191.4 | Q9: 85349.6 | R9: 80240.1 | S9: 79223.9 | T9: 75657.7 | U9: 82041.8 | V9: 82184.5 | W9: 92560.374 | X9: 102712.69 | Y9: 110438.46 | Z9: 107767.53
A10: Центральный федеральный округ | B10: 10180.1 | C10: 10611.2 | D10: 11929.5 | E10: 13297.3 | F10: 15297.1 | G10: 15257.3 | H10: 17344.7 | I10: 19894 | J10: 19134.2 | K10: 18893.4 | L10: 17461.3 | M10: 18064 | N10: 18178.53 | O10: 20254.8 | P10: 24547.2 | Q10: 25550.3 | R10: 23982.2 | S10: 24284.9 | T10: 23434.5 | U10: 25741.5 | V10: 25533.3 | W10: 29198.47 | X10: 32877.606 | Y10: 32964.146 | Z10: 30271.317
A11: Белгородская область | B11: 703.7 | C11: 595.4 | D11: 663.1 | E11: 671.2 | F11: 807.4 | G11: 830.8 | H11: 938.8 | I11: 1064 | J11: 1112.2 | K11: 1097.3 | L11: 1100.4 | M11: 1148.2 | N11: 1215.15 | O11: 1294.6 | P11: 1469.2 | Q11: 1554.9 | R11: 1350.1 | S11: 1300.5 | T11: 1215.5 | U11: 1260.4 | V11: 1148.6 | W11: 1165.183 | X11: 840.6 | Y11: 959.23 | Z11: 853.199
A12: Брянская область | B12: 225.3 | C12: 236.9 | D12: 241.7 | E12: 221.8 | F12: 229 | G12: 197.6 | H12: 246.3 | I12: 298.5 | J12: 321.7 | K12: 352.9 | L12: 390.9 | M12: 421.4 | N12: 453.02 | O12: 526.8 | P12: 550.7 | Q12: 644.3 | R12: 665.1 | S12: 558.3 | T12: 403.1 | U12: 407.1 | V12: 426.7 | W12: 451.47 | X12: 485.889 | Y12: 568.643 | Z12: 609.601
A13: Владимирская область | B13: 280.6 | C13: 246 | D13: 253.3 | E13: 279.4 | F13: 324.3 | G13: 326.9 | H13: 341.3 | I13: 376 | J13: 419.4 | K13: 451 | L13: 480.9 | M13: 437.6 | N13: 507.79 | O13: 518.9 | P13: 606 | Q13: 646.7 | R13: 655.7 | S13: 695.4 | T13: 652.8 | U13: 745.4 | V13: 726.2 | W13: 828.749 | X13: 1183.086 | Y13: 1145.389 | Z13: 1027.537
A14: Воронежская область | B14: 568.7 | C14: 584.6 | D14: 652.8 | E14: 750.2 | F14: 702.5 | G14: 784.4 | H14: 854.3 | I14: 974.4 | J14: 1120.5 | K14: 887.7 | L14: 1049.7 | M14: 996.2 | N14: 1110.37 | O14: 1348.7 | P14: 1572.9 | Q14: 1626.9 | R14: 1679 | S14: 1687.3 | T14: 1691.1 | U14: 1878.9 | V14: 1725.8 | W14: 1864.05 | X14: 1921.815 | Y14: 2014.485 | Z14: 1932.505
A15: Ивановская область | B15: 105.5 | C15: 91.6 | D15: 98.7 | E15: 119.7 | F15: 90.1 | G15: 105.5 | H15: 179.4 | I15: 142 | J15: 170.8 | K15: 186.5 | L15: 190.7 | M15: 216.6 | N15: 221.86 | O15: 232 | P15: 252.6 | Q15: 260.2 | R15: 176.8 | S15: 339.8 | T15: 369.1 | U15: 330.6 | V15: 333.2 | W15: 362.568 | X15: 392.393 | Y15: 511.905 | Z15: 460.166
A16: Калужская область | B16: 178.4 | C16: 194 | D16: 198.2 | E16: 216.7 | F16: 214.8 | G16: 262.7 | H16: 264.9 | I16: 458.2 | J16: 631.5 | K16: 456.7 | L16: 500.7 | M16: 598.4 | N16: 612.78 | O16: 657.1 | P16: 807.8 | Q16: 796.1 | R16: 737.3 | S16: 882.3 | T16: 787.2 | U16: 794.7 | V16: 819.3 | W16: 862.047 | X16: 916.291 | Y16: 1118.674 | Z16: 969.633
A17: Костромская область | B17: 157.1 | C17: 185 | D17: 112.2 | E17: 105 | F17: 81.7 | G17: 116.7 | H17: 109.3 | I17: 140.4 | J17: 149 | K17: 180.4 | L17: 151.4 | M17: 156.4 | N17: 204.67 | O17: 228.2 | P17: 328.3 | Q17: 322.4 | R17: 309.2 | S17: 310.2 | T17: 196.9 | U17: 211.8 | V17: 258.5 | W17: 334.527 | X17: 337.581 | Y17: 360.43 | Z17: 318.75
A18: Курская область | B18: 175.7 | C18: 192.7 | D18: 191.6 | E18: 275.9 | F18: 285.6 | G18: 297.5 | H18: 326.7 | I18: 375.8 | J18: 447.1 | K18: 456.1 | L18: 381.2 | M18: 394.4 | N18: 426.19 | O18: 496.1 | P18: 560.8 | Q18: 567.3 | R18: 586.7 | S18: 590.5 | T18: 594.8 | U18: 553.8 | V18: 522.9 | W18: 565.557 | X18: 553.556 | Y18: 619.49 | Z18: 721.52
A19: Липецкая область | B19: 321.2 | C19: 385.9 | D19: 304 | E19: 347.5 | F19: 421.2 | G19: 508 | H19: 620.7 | I19: 705 | J19: 721.9 | K19: 731.5 | L19: 736.8 | M19: 761.7 | N19: 807.01 | O19: 858.1 | P19: 1009.2 | Q19: 1060.5 | R19: 1077.9 | S19: 1084.2 | T19: 903 | U19: 1253.9 | V19: 1231.8 | W19: 1235.228 | X19: 755.389 | Y19: 770.887 | Z19: 791.212
A20: Московская область | B20: 2610.9 | C20: 2827.8 | D20: 3414.8 | E20: 4114.8 | F20: 5720.1 | G20: 5296.5 | H20: 6484 | I20: 7805.2 | J20: 7881.2 | K20: 8452 | L20: 7939 | M20: 8244.2 | N20: 6619.88 | O20: 7406.5 | P20: 9944.8 | Q20: 9623.3 | R20: 8913.7 | S20: 9077.7 | T20: 8866.6 | U20: 8613.5 | V20: 9040.3 | W20: 9215.12 | X20: 14096.284 | Y20: 12485.698 | Z20: 11404.45
... A32: Архангельская область | B32: 77.8 | C32: 99.8 | D32: 106.7 | E32: 94.1 | F32: 105 | G32: 117.6 | H32: 193.2 | I32: 259.6 | J32: 346.8 | K32: 243.5 | L32: 288.2 | M32: 283.2 | N32: 302.8 | O32: 326.9 | P32: 356.1 | Q32: 393.8 | R32: 366 | S32: 422.8 | T32: 322.6 | U32: 332.2 | V32: 373.9 | W32: 440.343 | X32: 462.148 | Y32: 462.324 | Z32: 478.639
A33: в том числе:
A34: Ненецкий автономный округ | B34: 12.2 | C34: 11.9 | D34: 4.8 | E34: 9.5 | F34: 8.3 | G34: 32.6 | H34: 35 | I34: 36.7 | J34: 63.9 | K34: 42.6 | L34: 42.3 | M34: 30.4 | N34: 33.5 | O34: 34.7 | P34: 34.9 | Q34: 35.5 | R34: 23.5 | S34: 27.9 | T34: 18.5 | U34: 10.1 | V34: 22.1 | W34: 17.788 | X34: 35.713 | Y34: 22 | Z34: 25
A35: Архангельская область без автономного округа | B35: 65.6 | C35: 88 | D35: 102 | E35: 85 | F35: 97 | G35: 85 | H35: 158 | I35: 223 | J35: 283 | K35: 201 | L35: 245.9 | M35: 252.8 | N35: 269.3 | O35: 292.2 | P35: 321.2 | Q35: 358.3 | R35: 342.5 | S35: 394.9 | T35: 304 | U35: 322.1 | V35: 351.8 | W35: 422.555 | X35: 426.435 | Y35: 440.616 | Z35: 453.415
A36: Вологодская область | B36: 204.5 | C36: 239.4 | D36: 238.5 | E36: 247 | F36: 300.1 | G36: 293 | H36: 333.7 | I36: 488.7 | J36: 545.4 | K36: 489.9 | L36: 410 | M36: 434.4 | N36: 389.05 | O36: 575.5 | P36: 774.4 | Q36: 863.6 | R36: 774 | S36: 542.3 | T36: 535.5 | U36: 585.1 | V36: 500 | W36: 639.055 | X36: 648.001 | Y36: 746.028 | Z36: 682.685
A37: Калининградская область | B37: 171.8 | C37: 175.7 | D37: 198 | E37: 232.3 | F37: 245 | G37: 266 | H37: 501.8 | I37: 753.3 | J37: 800.6 | K37: 607.8 | L37: 524.6 | M37: 544.9 | N37: 581.91 | O37: 638.7 | P37: 1115.9 | Q37: 1207.2 | R37: 1208.6 | S37: 902.4 | T37: 916 | U37: 973 | V37: 1164 | W37: 1270.905 | X37: 1318.535 | Y37: 1216.738 | Z37: 1220.564
A38: Ленинградская область | B38: 391.5 | C38: 414.7 | D38: 433.2 | E38: 444.2 | F38: 510.8 | G38: 532.9 | H38: 671.4 | I38: 844 | J38: 908 | K38: 1030.7 | L38: 1043.5 | M38: 1075.9 | N38: 1149.43 | O38: 1360.2 | P38: 1787.6 | Q38: 2323 | R38: 2171.7 | S38: 2625.8 | T38: 2640.6 | U38: 2930.2 | V38: 2666 | W38: 3386.445 | X38: 3968.658 | Y38: 4186.404 | Z38: 4065.041
A39: Мурманская область | B39: 27.9 | C39: 7.8 | D39: 4.5 | E39: 13.3 | F39: 6.5 | G39: 8.1 | H39: 13.7 | I39: 12.7 | J39: 9.4 | K39: 22.1 | L39: 27.6 | M39: 23.2 | N39: 24.33 | O39: 24.8 | P39: 25.1 | Q39: 33.4 | R39: 59.2 | S39: 71 | T39: 46.3 | U39: 44.8 | V39: 35.6 | W39: 50.779 | X39: 180.392 | Y39: 60.702 | Z39: 72.154
A40: Новгородская область | B40: 89 | C40: 93.9 | D40: 97.5 | E40: 109.4 | F40: 148.2 | G40: 143.1 | H40: 163.1 | I40: 204.5 | J40: 258.5 | K40: 246.2 | L40: 232.6 | M40: 270.7 | N40: 313.39 | O40: 323.1 | P40: 354 | Q40: 359.3 | R40: 361.9 | S40: 231.6 | T40: 264.4 | U40: 286.6 | V40: 282.5 | W40: 307.453 | X40: 343.908 | Y40: 376.954 | Z40: 337.851
A41: Псковская область | B41: 81.8 | C41: 92.4 | D41: 100.4 | E41: 113.6 | F41: 132.4 | G41: 99.6 | H41: 125.5 | I41: 131.3 | J41: 151.4 | K41: 191.8 | L41: 149.7 | M41: 177.7 | N41: 214.66 | O41: 184.6 | P41: 298 | Q41: 350.5 | R41: 272.3 | S41: 202.3 | T41: 235.9 | U41: 302.2 | V41: 272.6 | W41: 314.494 | X41: 339.62 | Y41: 378.992 | Z41: 361.734
A42: г. Санкт-Петербург | B42: 1080.9 | C42: 1118.2 | D42: 1213.7 | E42: 1757.9 | F42: 2032 | G42: 2273.4 | H42: 2375.7 | I42: 2636.9 | J42: 3211.6 | K42: 2603.2 | L42: 2656.5 | M42: 2705.7 | N42: 2576.53 | O42: 2583.5 | P42: 3261.8 | Q42: 3030.7 | R42: 3116.3 | S42: 3536.1 | T42: 3950.3 | U42: 3471.2 | V42: 3369.6 | W42: 3463.836 | X42: 3474.169 | Y42: 3482.663 | Z42: 2666.153
A43: Южный федеральный округ | B43: 3337.4 | C43: =SUM(C44:C50) -> 3450.7 | D43: =SUM(D44:D50) -> 3782 | E43: =SUM(E44:E50) -> 3687 | F43: =SUM(F44:F50) -> 4159.3 | G43: 4408.9 | H43: =SUM(H44:H50) -> 5504.6 | I43: =SUM(I44:I50) -> 7043.7 | J43: =SUM(J44:J50) -> 7288.7 | K43: =SUM(K44:K50) -> 6614.4 | L43: 6803.1 | M43: 6931.1 | N43: 7933.89 | O43: 7705.7 | P43: 10097.6 | Q43: 9320.1 | R43: 8962 | S43: 9622.1 | T43: 9067.3 | U43: 9920.1 | V43: 10701.1 | W43: 11999.141 | X43: 13760.758 | Y43: 14592.851 | Z43: 13553.267
A44: Республика Адыгея | B44: 67.8 | C44: 73.4 | D44: 118.1 | E44: 58.2 | F44: 39.6 | G44: 71.6 | H44: 42.1 | I44: 68.7 | J44: 80.8 | K44: 125.7 | L44: 135 | M44: 122.3 | N44: 97.74 | O44: 106.9 | P44: 270.9 | Q44: 296.5 | R44: 235.2 | S44: 244.3 | T44: 187 | U44: 257 | V44: 258.1 | W44: 307.097 | X44: 467.989 | Y44: 564.038 | Z44: 565.617
A45: Республика Калмыкия | B45: 36.8 | C45: 77 | D45: 64 | E45: 50.2 | F45: 51.8 | G45: 48.8 | H45: 62.8 | I45: 77.7 | J45: 59.3 | K45: 72.3 | L45: 87.3 | M45: 103.9 | N45: 85.23 | O45: 111 | P45: 125.2 | Q45: 126 | R45: 70.8 | S45: 96.3 | T45: 90.4 | U45: 101.2 | V45: 87.5 | W45: 121.968 | X45: 123.03 | Y45: 142.004 | Z45: 130.876
A46: Республика Крым | P46: 634.2 | Q46: 252.6 | R46: 285.5 | S46: 833.7 | T46: 774.9 | U46: 799.7 | V46: 809 | W46: 742.655 | X46: 927.194 | Y46: 1219.572 | Z46: 1239.805
A47: Краснодарский край | B47: 1391.6 | C47: 1440.2 | D47: 1645 | E47: 1580.1 | F47: 1809.6 | G47: 1939.5 | H47: 2704.8 | I47: 3704.1 | J47: 3937.6 | K47: 3411.7 | L47: 3605.5 | M47: 3691.7 | N47: 4371 | O47: 3948.7 | P47: 4759 | Q47: 4644.3 | R47: 4502 | S47: 4728.4 | T47: 4414.9 | U47: 4532 | V47: 5124.3 | W47: 6283.122 | X47: 7592.631 | Y47: 7640.374 | Z47: 6682.412
A48: Астраханская область | B48: 484.9 | C48: 496.4 | D48: 520.9 | E48: 582.1 | F48: 630.6 | G48: 648.3 | H48: 668.8 | I48: 725.3 | J48: 382.4 | K48: 476.4 | L48: 499.7 | M48: 504.3 | N48: 511.11 | O48: 595.2 | P48: 623.7 | Q48: 575.3 | R48: 602.9 | S48: 483.5 | T48: 328.3 | U48: 318.5 | V48: 365 | W48: 543.423 | X48: 590.782 | Y48: 632.092 | Z48: 601.303
A49: Волгоградская область | B49: 400.5 | C49: 407.3 | D49: 450.1 | E49: 411.8 | F49: 508.5 | G49: 514.8 | H49: 638 | I49: 762.3 | J49: 820.2 | K49: 723.1 | L49: 666.9 | M49: 628.7 | N49: 884.78 | O49: 810.3 | P49: 1115 | Q49: 911.7 | R49: 754 | S49: 727.6 | T49: 610.2 | U49: 731.4 | V49: 770.7 | W49: 796.755 | X49: 798.495 | Y49: 951.05 | Z49: 1036.167
A50: Ростовская область | B50: 955.8 | C50: 956.4 | D50: 983.9 | E50: 1004.6 | F50: 1119.2 | G50: 1185.9 | H50: 1388.1 | I50: 1705.6 | J50: 2008.4 | K50: 1805.2 | L50: 1808.6 | M50: 1880.3 | N50: 1984.03 | O50: 2133.6 | P50: 2325 | Q50: 2408.7 | R50: 2293.1 | S50: 2333.9 | T50: 2347.4 | U50: 2611.3 | V50: 2644.3 | W50: 2686.079 | X50: 2703.722 | Y50: 2963.427 | Z50: 2950.859
A51: г. Севастополь | P51: 244.6 | Q51: 105 | R51: 218.5 | S51: 174.3 | T51: 314.3 | U51: 568.9 | V51: 642.4 | W51: 518.042 | X51: 556.915 | Y51: 480.294 | Z51: 346.228
A52: Северо-Кавказский федеральный округ | B52: 1493.1 | C52: =SUM(C53:C59) -> 1610.8 | D52: =SUM(D53:D59) -> 1500.7 | E52: =SUM(E53:E59) -> 1591.9 | F52: =SUM(F53:F59) -> 1664.5 | G52: 1803.8 | H52: =SUM(H53:H59) -> 2082.9 | I52: =SUM(I53:I59) -> 2527.6 | J52: =SUM(J53:J59) -> 2629.1 | K52: =SUM(K53:K59) -> 2799.9 | L52: 3030.6 | M52: 3192.5 | N52: 3749.3 | O52: 4141.5 | P52: 5011.9 | Q52: 4996.7 | R52: 5031 | S52: 5081.7 | T52: 3557.3 | U52: 4027.5 | V52: 3995.8 | W52: 4718.571 | X52: 5970.292 | Y52: 7364.082 | Z52: 9062.837
...

Sheet 14.3.2.
A2: Социально-экономические показатели по субъектам Российской Федерации
A3: 14. СТРОИТЕЛЬСТВО
A4: ЖИЛИЩНОЕ И СОЦИАЛЬНО-КУЛЬТУРНОЕ СТРОИТЕЛЬСТВО
A5: 14.3. ВВОД В ДЕЙСТВИЕ ЖИЛЫХ ДОМОВ
A6: 14.3.2. На 1000 человек населения
A7: (квадратных метров общей площади жилых помещений)
B8: 2000 | C8: 2001 | D8: 2002 | E8: 2003 | F8: 2004 | G8: 2005 | H8: 2006 | I8: 2007 | J8: 2008 | K8: 2009 | L8: 2010 | M8: 2011 | N8: 2012 | O8: 2013 | P8: 2014 | Q8: 2015 | R8: 2016 | S8: 2017 | T8: 2018 | U8: 2019 | V8: 2020 | W8: 2021 | X8: 2022 | Y8: 2023 | Z8: 2024
A9: Российская Федерация | B9: 206.66058 | C9: 217.18016 | D9: 232.83336 | E9: 251.98512 | F9: 284.86753 | G9: 304 | H9: 353.38852 | I9: 428.70524 | J9: 448.76936 | K9: 419.452 | L9: 409 | M9: 435 | N9: 459 | O9: 490 | P9: 575 | Q9: 581 | R9: 544 | S9: 536 | T9: 512 | U9: 555 | V9: 556 | W9: 629 | X9: 700 | Y9: 755 | Z9: 737
A10: Центральный федеральный округ | B10: 266.485 | C10: 278.34992 | D10: 313.87144 | E10: 350.33514 | F10: 402.50685 | G10: 401 | H10: 454.69034 | I10: 520.83005 | J10: 500.41488 | K10: 493.31269 | L10: 455 | M10: 469 | N10: 469 | O10: 519 | P10: 625 | Q10: 647 | R10: 603 | S10: 608 | T10: 583 | U10: 638 | V10: 632 | W10: 724 | X10: 816 | Y10: 820 | Z10: 752
A11: Белгородская область | B11: 467.79233 | C11: 394.93234 | D11: 439.13907 | E11: 443.65742 | F11: 533.72608 | G11: 550 | H11: 620.51616 | I11: 701.3256 | J11: 730.18291 | K11: 717.64968 | L11: 718 | M11: 748 | N11: 789 | O11: 839 | P11: 949 | Q11: 1002 | R11: 869 | S11: 837 | T11: 783 | U11: 812 | V11: 741 | W11: 756 | X11: 551 | Y11: 636 | Z11: 572
A12: Брянская область | B12: 159.15513 | C12: 169.25055 | D12: 174.73973 | E12: 162.17884 | F12: 169.3549 | G12: 148 | H12: 186.56264 | I12: 228.20298 | J12: 247.69075 | K12: 273.48215 | L12: 305 | M12: 332 | N12: 360 | O12: 423 | P12: 446 | Q12: 525 | R12: 545 | S12: 460 | T12: 335 | U12: 341 | V12: 360 | W12: 385 | X12: 419 | Y12: 496 | Z12: 536
A13: Владимирская область | B13: 179.09114 | C13: 158.85316 | D13: 165.59885 | E13: 184.44509 | F13: 215.68451 | G13: 219 | H13: 230.42797 | I13: 255.55596 | J13: 286.80061 | K13: 310.20975 | L13: 333 | M13: 304 | N13: 355 | O13: 365 | P13: 428 | Q13: 459 | R13: 467 | S13: 498 | T13: 471 | U13: 541 | V13: 531 | W13: 614 | X13: 887 | Y13: 869 | Z13: 788
A14: Воронежская область | B14: 233.85969 | C14: 242.60281 | D14: 273.61891 | E14: 316.41205 | F14: 296.89028 | G14: 332 | H14: 362.39723 | I14: 414.79557 | J14: 478.49751 | K14: 379.85473 | L14: 450 | M14: 427 | N14: 476 | O14: 578 | P14: 674 | Q14: 696 | R14: 717 | S14: 720 | T14: 722 | U14: 804 | V14: 741 | W14: 807 | X14: 838 | Y14: 884 | Z14: 853
A15: Ивановская область | B15: 88.894506 | C15: 78.263841 | D15: 85.587929 | E15: 105.2046 | F15: 80.168487 | G15: 95 | H15: 163.70869 | I15: 130.81831 | J15: 158.48419 | K15: 174.12852 | L15: 179 | M15: 205 | N15: 213 | O15: 224 | P15: 247 | Q15: 257 | R15: 177 | S15: 344 | T15: 379 | U15: 345 | V15: 352 | W15: 389 | X15: 427 | Y15: 562 | Z15: 510
A16: Калужская область | B16: 167.46456 | C16: 183.90369 | D16: 189.82856 | E16: 209.34467 | F16: 208.62106 | G16: 256 | H16: 259.26336 | I16: 449.68565 | J16: 621.15039 | K16: 449.81912 | L16: 495 | M16: 592 | N16: 604 | O16: 645 | P16: 787 | Q16: 770 | R16: 707 | S16: 841 | T16: 748 | U16: 755 | V16: 777 | W16: 810 | X16: 855 | Y16: 1046 | Z16: 908
A17: Костромская область | B17: 207.28328 | C17: 246.99599 | D17: 151.78571 | E17: 144.07284 | F17: 113.85807 | G17: 165 | H17: 157.31417 | I17: 204.48111 | J17: 218.92287 | K17: 267.11442 | L17: 226 | M17: 236 | N17: 313 | O17: 352 | P17: 512 | Q17: 508 | R17: 492 | S17: 500 | T17: 322 | U17: 352 | V17: 435 | W17: 573 | X17: 587 | Y17: 633 | Z17: 566
A18: Курская область | B18: 137.90126 | C18: 153.24056 | D18: 154.54106 | E18: 225.734 | F18: 237.09273 | G18: 251 | H18: 279.32507 | I18: 324.88416 | J18: 389.59805 | K18: 400.38309 | L18: 337 | M18: 351 | N18: 381 | O18: 444 | P18: 502 | Q18: 508 | R18: 524 | S18: 529 | T18: 537 | U18: 503 | V18: 477 | W18: 521 | X18: 516 | Y18: 582 | Z18: 684
A19: Липецкая область | B19: 260.94727 | C19: 315.20052 | D19: 250.06169 | E19: 287.63223 | F19: 350.43755 | G19: 425 | H19: 520.65639 | I19: 593.15624 | J19: 609.53574 | K19: 620.16963 | L19: 627 | M19: 651 | N19: 691 | O19: 736 | P19: 865 | Q19: 909 | R19: 923 | S19: 929 | T19: 776 | U19: 1080 | V19: 1066 | W19: 1079 | X19: 667 | Y19: 688 | Z19: 711
A20: Московская область | B20: 394.34812 | C20: 427.72223 | D20: 516.37683 | E20: 619.3162 | F20: 853.23267 | G20: 783 | H20: 951.38362 | I20: 1135.947 | J20: 1137.8014 | K20: 1208.9638 | L20: 1124 | M20: 1149 | N20: 905 | O20: 994 | P20: 1310 | Q20: 1244 | R20: 1131 | S20: 1131 | T20: 1086 | U20: 1037 | V20: 1076 | W20: 1085 | X20: 1645 | Y20: 1448 | Z20: 1309
... A32: Архангельская область | B32: 56.38907 | C32: 73.393146 | D32: 79.537831 | E32: 71.067033 | F32: 80.313053 | G32: 91 | H32: 151.61836 | I32: 205.71909 | J32: 277.06674 | K32: 196.07859 | L32: 234 | M32: 233 | N32: 254 | O32: 279 | P32: 308 | Q32: 346 | R32: 327 | S32: 384 | T32: 298 | U32: 312 | V32: 357 | W32: 429 | X32: 457 | Y32: 461 | Z32: 482
A33: в том числе:
A34: Ненецкий автономный округ | B34: 296.83698 | C34: 290.95355 | D34: 116.22276 | E34: 227.32711 | F34: 198.11906 | G34: 778 | H34: 835.6413 | I34: 876.37605 | J34: 1525.8244 | K34: 1014.6239 | L34: 1005 | M34: 722 | N34: 794 | O34: 821 | P34: 826 | Q34: 837 | R34: 554 | S34: 662 | T34: 442 | U34: 243 | V34: 531 | W34: 429 | X34: 863 | Y34: 519 | Z34: 600
A35: Архангельская область без автономного округа | B35: 49.006425 | C35: 66.646448 | D35: 78.372558 | E35: 65.974583 | F35: 76.413089 | G35: 68 | H35: 128.37075 | I35: 182.69923 | J35: 233.83934 | K35: 167.43578 | L35: 207 | M35: 216 | N35: 234 | O35: 258 | P35: 289 | Q35: 327 | R35: 318 | S35: 373 | T35: 292 | U35: 315 | V35: 350 | W35: 429 | X35: 440 | Y35: 459 | Z35: 476
A36: Вологодская область | B36: 157.91506 | C36: 186.37602 | D36: 187.39687 | E36: 195.81635 | F36: 239.91762 | G36: 236 | H36: 271.22143 | I36: 399.66404 | J36: 448.16776 | K36: 404.45854 | L36: 340 | M36: 362 | N36: 325 | O36: 482 | P36: 650 | Q36: 726 | R36: 653 | S36: 460 | T36: 457 | U36: 503 | V36: 433 | W36: 558 | X36: 572 | Y36: 663 | Z36: 610
A37: Калининградская область | B37: 179.31322 | C37: 183.69054 | D37: 207.37327 | E37: 244.27176 | F37: 259.26118 | G37: 283 | H37: 536.42517 | I37: 805.82875 | J37: 855.383 | K37: 648.23495 | L37: 558 | M37: 577 | N37: 612 | O37: 666 | P37: 1154 | Q37: 1239 | R37: 1230 | S37: 909 | T37: 916 | U37: 963 | V37: 1143 | W37: 1238 | X37: 1278 | Y37: 1178 | Z37: 1181
A38: Ленинградская область | B38: 232.55123 | C38: 247.36057 | D38: 259.41673 | E38: 265.95315 | F38: 304.52507 | G38: 317 | H38: 397.69133 | I38: 498.86396 | J38: 535.46008 | K38: 605.61654 | L38: 610 | M38: 622 | N38: 655 | O38: 765 | P38: 994 | Q38: 1280 | R38: 1186 | S38: 1414 | T38: 1395 | U38: 1516 | V38: 1357 | W38: 1700 | X38: 1970 | Y38: 2063 | Z38: 1985
A39: Мурманская область | B39: 29.935622 | C39: 8.5311167 | D39: 5.0122522 | E39: 15.088312 | F39: 7.514086 | G39: 10 | H39: 16.472226 | I39: 15.496139 | J39: 11.599969 | K39: 27.533486 | L39: 35 | M39: 29 | N39: 31 | O39: 33 | P39: 34 | Q39: 45 | R39: 81 | S39: 98 | T39: 65 | U39: 64 | V39: 52 | W39: 76 | X39: 273 | Y39: 92 | Z39: 110
A40: Новгородская область | B40: 124.58007 | C40: 133.07823 | D40: 139.98564 | E40: 159.11524 | F40: 218.34511 | G40: 214 | H40: 246.52358 | I40: 312.26571 | J40: 398.43769 | K40: 383.17098 | L40: 366 | M40: 429 | N40: 500 | O40: 519 | P40: 572 | Q40: 584 | R40: 592 | S40: 382 | T40: 440 | U40: 482 | V40: 478 | W40: 526 | X40: 594 | Y40: 657 | Z40: 594
A41: Псковская область | B41: 103.87302 | C41: 119.11822 | D41: 131.43082 | E41: 150.9767 | F41: 178.76552 | G41: 137 | H41: 175.64681 | I41: 186.52873 | J41: 217.85332 | K41: 279.54538 | L41: 221 | M41: 266 | N41: 324 | O41: 282 | P41: 460 | Q41: 546 | R41: 428 | S41: 321 | T41: 379 | U41: 491 | V41: 448 | W41: 523 | X41: 573 | Y41: 648 | Z41: 626
A42: г. Санкт-Петербург | B42: 228.59741 | C42: 237.83393 | D42: 259.75944 | E42: 377.292 | F42: 434.72085 | G42: 484 | H42: 502.24071 | I42: 554.41237 | J42: 671.63148 | K42: 540.56119 | L42: 546 | M42: 548 | N42: 513 | O42: 503 | P42: 623 | Q42: 571 | R42: 581 | S42: 649 | T42: 716 | U42: 624 | V42: 603 | W42: 619 | X42: 620 | Y42: 622 | Z42: 474
A43: Южный федеральный округ | B43: 237.05145 | C43: 245.86391 | D43: 270.50417 | E43: 264.67935 | F43: 299.48141 | G43: 318 | H43: 398.05412 | I43: 509.53955 | J43: 526.80328 | K43: 477.60387 | L43: 491 | M43: 499 | N43: 570 | O43: 551 | P43: 619 | Q43: 567 | R43: 542 | S43: 579 | T43: 544 | U43: 593 | V43: 639 | W43: 717 | X43: 825 | Y43: 877 | Z43: 816
A44: Республика Адыгея | B44: 151.27175 | C44: 164.20582 | D44: 264.38325 | E44: 130.54069 | F44: 89.174327 | G44: 162 | H44: 95.725765 | I44: 156.75912 | J44: 184.20573 | K44: 285.96128 | L44: 307 | M44: 276 | N44: 218 | O44: 236 | P44: 593 | Q44: 641 | R44: 503 | S44: 518 | T44: 394 | U44: 533 | V44: 528 | W44: 621 | X44: 939 | Y44: 1130 | Z44: 1130
A45: Республика Калмыкия | B45: 119.55815 | C45: 254.62963 | D45: 217.17 | E45: 171.91251 | F45: 176.98873 | G45: 166 | H45: 214.14225 | I45: 265.79278 | J45: 203.80388 | K45: 249.33184 | L45: 302 | M45: 361 | N45: 299 | O45: 393 | P45: 446 | Q45: 452 | R45: 255 | S45: 349 | T45: 331 | U45: 374 | V45: 325 | W45: 456 | X45: 463 | Y45: 535 | Z45: 490
A46: Республика Крым | P46: 337 | Q46: 133 | R46: 149 | S46: 433 | T46: 401 | U46: 413 | V46: 418 | W46: 384 | X46: 482 | Y46: 637 | Z46: 651
